<?xml version="1.0" ?>
<!-- =================================================================================== -->
<!-- |    This document was autogenerated by xacro from xacro/moma.xacro               | -->
<!-- |    EDITING THIS FILE BY HAND IS NOT RECOMMENDED                                 | -->
<!-- =================================================================================== -->
<robot name="mobile_manipulation">
  <!-- Run the macros -->
  <link name="link_yaw" />


    
  <link name="armbase_link">
    <inertial>
      <origin rpy="0 0 0" xyz="-0.000648 -0.000166 0.084487"/>
      <mass value="1.697"/>
      <inertia ixx="0.004622" ixy="9E-06" ixz="6E-05" iyy="0.004495" iyz="9E-06" izz="0.002079"/>
    </inertial>
    <visual>
      <origin rpy="0 0 0" xyz="0 0 0"/>
      <geometry>
        <mesh filename="package://moma_description/arms/gen3/6dof/meshes/base_link.STL"/>
      </geometry>
      <material name="">
        <color rgba="0.75294 0.75294 0.75294 1"/>
      </material>
    </visual>
    <collision>
      <origin rpy="0 0 0" xyz="0 0 0"/>
      <geometry>
        <mesh filename="package://moma_description/arms/gen3/6dof/meshes/base_link.STL"/>
      </geometry>
    </collision>
  </link>
  <link name="armshoulder_link">
    <inertial>
      <origin rpy="0 0 0" xyz="-2.3E-05 -0.010364 -0.07336"/>
      <mass value="1.377"/>
      <inertia ixx="0.00457" ixy="1E-06" ixz="2E-06" iyy="0.004831" iyz="0.000448" izz="0.001409"/>
    </inertial>
    <visual>
      <origin rpy="0 0 0" xyz="0 0 0"/>
      <geometry>
        <mesh filename="package://moma_description/arms/gen3/6dof/meshes/shoulder_link.STL"/>
      </geometry>
      <material name="">
        <color rgba="0.75294 0.75294 0.75294 1"/>
      </material>
    </visual>
    <collision>
      <origin rpy="0 0 0" xyz="0 0 0"/>
      <geometry>
        <mesh filename="package://moma_description/arms/gen3/6dof/meshes/shoulder_link.STL"/>
      </geometry>
    </collision>
  </link>
  <joint name="joint_yaw" type="revolute">
        <parent link="link_yaw" />
        <child link="base_link" />
        <axis xyz="0 0 1" />
        <origin rpy="0 0 0" xyz="0 0 0" />
        <limit effort="1000.0" lower="-3.1415" upper="3.1415" velocity="1.3963" />
  </joint>


  <joint name="armjoint_1" type="revolute">
    <origin rpy="-3.1416 0.0 0.0" xyz="0 0 0.15643"/>
    <parent link="armbase_link"/>
    <child link="armshoulder_link"/>
    <axis xyz="0 0 1"/>
    <limit effort="39.0" lower="-6.28" upper="6.28" velocity="1.3963" />
  </joint>
  <link name="armbicep_link">
    <inertial>
      <origin rpy="0 0 0" xyz="3.5E-05 -0.208207 -0.01889"/>
      <mass value="1.262"/>
      <inertia ixx="0.046752" ixy="-9E-06" ixz="0" iyy="0.00085" iyz="-9.8E-05" izz="0.047188"/>
    </inertial>
    <visual>
      <origin rpy="0 0 0" xyz="0 0 0"/>
      <geometry>
        <mesh filename="package://moma_description/arms/gen3/6dof/meshes/bicep_link.STL"/>
      </geometry>
      <material name="">
        <color rgba="0.75294 0.75294 0.75294 1"/>
      </material>
    </visual>
    <collision>
      <origin rpy="0 0 0" xyz="0 0 0"/>
      <geometry>
        <mesh filename="package://moma_description/arms/gen3/6dof/meshes/bicep_link.STL"/>
      </geometry>
    </collision>
  </link>
  <joint name="armjoint_2" type="revolute">
    <origin rpy="1.5708 0.0 0.0" xyz="0 0.005375 -0.12838"/>
    <parent link="armshoulder_link"/>
    <child link="armbicep_link"/>
    <axis xyz="0 0 1"/>
    <limit effort="39" lower="-2.24" upper="2.24" velocity="1.3963"/>
  </joint>
  <link name="armforearm_link">
    <inertial>
      <origin rpy="0 0 0" xyz="1.8E-05 0.076168 -0.01397"/>
      <mass value="0.93"/>
      <inertia ixx="0.008292" ixy="-1E-06" ixz="0" iyy="0.000628" iyz="0.000432" izz="0.008464"/>
    </inertial>
    <visual>
      <origin rpy="0 0 0" xyz="0 0 0"/>
      <geometry>
        <mesh filename="package://moma_description/arms/gen3/6dof/meshes/forearm_link.STL"/>
      </geometry>
      <material name="">
        <color rgba="0.75294 0.75294 0.75294 1"/>
      </material>
    </visual>
    <collision>
      <origin rpy="0 0 0" xyz="0 0 0"/>
      <geometry>
        <mesh filename="package://moma_description/arms/gen3/6dof/meshes/forearm_link.STL"/>
      </geometry>
    </collision>
  </link>
  <joint name="armjoint_3" type="revolute">
    <origin rpy="3.1416 0 0" xyz="0 -0.41 0"/>
    <parent link="armbicep_link"/>
    <child link="armforearm_link"/>
    <axis xyz="0 0 1"/>
    <limit effort="39" lower="-2.57" upper="2.57" velocity="1.3963"/>
  </joint>
  <link name="armspherical_wrist_1_link">
    <inertial>
      <origin rpy="0 0 0" xyz="-1E-06 0.008486 -0.062937"/>
      <mass value="0.6781"/>
      <inertia ixx="0.001645" ixy="0" ixz="0" iyy="0.001666" iyz="-0.000234" izz="0.000389"/>
    </inertial>
    <visual>
      <origin rpy="0 0 0" xyz="0 0 0"/>
      <geometry>
        <mesh filename="package://moma_description/arms/gen3/6dof/meshes/spherical_wrist_1_link.STL"/>
      </geometry>
      <material name="">
        <color rgba="0.75294 0.75294 0.75294 1"/>
      </material>
    </visual>
    <collision>
      <origin rpy="0 0 0" xyz="0 0 0"/>
      <geometry>
        <mesh filename="package://moma_description/arms/gen3/6dof/meshes/spherical_wrist_1_link.STL"/>
      </geometry>
    </collision>
  </link>
  <joint name="armjoint_4" type="revolute">
    <origin rpy="1.5708 0.0 0.0" xyz="0 0.20843 -0.006375"/>
    <parent link="armforearm_link"/>
    <child link="armspherical_wrist_1_link"/>
    <axis xyz="0 0 1" />
        <limit effort="9.0" lower="-6.28" upper="6.28" velocity="1.2218" />
  </joint>
  <link name="armspherical_wrist_2_link">
    <inertial>
      <origin rpy="0 0 0" xyz="-1E-06 0.046429 -0.008704"/>
      <mass value="0.678"/>
      <inertia ixx="0.001685" ixy="0" ixz="0" iyy="0.0004" iyz="0.000255" izz="0.001696"/>
    </inertial>
    <visual>
      <origin rpy="0 0 0" xyz="0 0 0"/>
      <geometry>
        <mesh filename="package://moma_description/arms/gen3/6dof/meshes/spherical_wrist_2_link.STL"/>
      </geometry>
      <material name="">
        <color rgba="0.75294 0.75294 0.75294 1"/>
      </material>
    </visual>
    <collision>
      <origin rpy="0 0 0" xyz="0 0 0"/>
      <geometry>
        <mesh filename="package://moma_description/arms/gen3/6dof/meshes/spherical_wrist_2_link.STL"/>
      </geometry>
    </collision>
  </link>
  <joint name="armjoint_5" type="revolute">
    <origin rpy="-1.5708 0.0 0.0" xyz="0 -0.00017505 -0.10593"/>
    <parent link="armspherical_wrist_1_link"/>
    <child link="armspherical_wrist_2_link"/>
    <axis xyz="0 0 1"/>
    <limit effort="9" lower="-2.09" upper="2.09" velocity="1.2218"/>
  </joint>
  <link name="armbracelet_link">
    <inertial>
      <origin rpy="0 0 0" xyz="0.000281 0.011402 -0.029798"/>
      <mass value="0.5"/>
      <inertia ixx="0.000587" ixy="3E-06" ixz="3E-06" iyy="0.000369" iyz="-0.000118" izz="0.000609"/>
    </inertial>
    <visual>
      <origin rpy="0 0 0" xyz="0 0 0"/>
      <geometry>
        <mesh filename="package://moma_description/arms/gen3/6dof/meshes/bracelet_with_vision_link.STL"/>
      </geometry>
      <material name="">
        <color rgba="0.75294 0.75294 0.75294 1"/>
      </material>
    </visual>
    <collision>
      <origin rpy="0 0 0" xyz="0 0 0"/>
      <geometry>
        <mesh filename="package://moma_description/arms/gen3/6dof/meshes/bracelet_with_vision_link.STL"/>
      </geometry>
    </collision>
  </link>
  <joint name="armjoint_6" type="revolute">
    <origin rpy="1.5708 0.0 0.0" xyz="0 0.10593 -0.00017505"/>
    <parent link="armspherical_wrist_2_link"/>
    <child link="armbracelet_link"/>
    <axis xyz="0 0 1"/>
    <limit effort="9.0" lower="-3.341" upper="3.341" velocity="1.2218" />
  </joint>
  <link name="armend_effector_link"/>
  <joint name="armend_effector" type="fixed">
    <origin rpy="3.14159265358979 1.09937075168372E-32 3.14159265358979" xyz="0 0 -0.0615250000000001"/>
    <parent link="armbracelet_link"/>
    <child link="armend_effector_link"/>
    <axis xyz="0 0 0"/>
  </joint>
  <link name="armcamera_link"/>
  <joint name="armcamera_module" type="fixed">
    <origin rpy="3.14159265358979 3.14159265358979 0" xyz="0 0.05639 -0.00305"/>
    <parent link="armend_effector_link"/>
    <child link="armcamera_link"/>
  </joint>
  <link name="armcamera_depth_frame"/>
  <joint name="armdepth_module" type="fixed">
    <origin rpy="3.14159265358979 3.14159265358979 0" xyz="0.0275 0.066 -0.00305"/>
    <parent link="armend_effector_link"/>
    <child link="armcamera_depth_frame"/>
  </joint>
  <link name="armcamera_color_frame"/>
  <joint name="armcolor_module" type="fixed">
    <origin rpy="3.14159265358979 3.14159265358979 0" xyz="0 0.05639 -0.00305"/>
    <parent link="armend_effector_link"/>
    <child link="armcamera_color_frame"/>
  </joint>
  <!-- This line was removed by Kinova because we replaced the transmission file with our own 
    <xacro:include filename="$(find robotiq_2f_85_gripper_visualization)/urdf/robotiq_arg2f_transmission.xacro" /> -->
  <!-- Tool frame used by the arm -->
  <link name="armtool_frame"/>
  <joint name="armtool_frame_joint" type="fixed">
    <origin rpy="0 0 0" xyz="0 0 0.120"/>
    <parent link="armend_effector_link"/>
    <child link="armtool_frame"/>
    <axis xyz="0 0 0"/>
  </joint>
  <!-- This joint was added by Kinova -->
  <joint name="armgripper_base_joint" type="fixed">
    <parent link="armend_effector_link"/>
    <child link="armrobotiq_arg2f_base_link"/>
    <origin rpy="0.0 0.0 1.57" xyz="0.0 0.0 0.0"/>
  </joint>
  <link name="armrobotiq_arg2f_base_link">
    <inertial>
      <origin rpy="0 0 0" xyz="8.625E-08 -4.6583E-06 0.03145"/>
      <mass value="0.22652"/>
      <inertia ixx="0.00020005" ixy="-4.2442E-10" ixz="-2.9069E-10" iyy="0.00017832" iyz="-3.4402E-08" izz="0.00013478"/>
    </inertial>
    <visual>
      <origin rpy="0 0 0" xyz="0 0 0"/>
      <geometry>
        <!-- The DAE file doesn't show well in Gazebo so we're using the STL instead -->
        <!-- <mesh filename="package://moma_description/grippers/robotiq_2f_85/meshes/visual/robotiq_arg2f_85_base_link.dae" scale="0.001 0.001 0.001"/> -->
        <mesh filename="package://moma_description/grippers/robotiq_2f_85/meshes/collision/robotiq_arg2f_base_link.stl"/>
      </geometry>
      <material name="">
        <color rgba="0.1 0.1 0.1 1"/>
      </material>
    </visual>
    <collision>
      <origin rpy="0 0 0" xyz="0 0 0"/>
      <geometry>
        <mesh filename="package://moma_description/grippers/robotiq_2f_85/meshes/collision/robotiq_arg2f_base_link.stl"/>
      </geometry>
    </collision>
  </link>
  <gazebo reference="armrobotiq_arg2f_base_link">
    <material>Gazebo/Black</material>
  </gazebo>
  <link name="armleft_outer_knuckle">
    <inertial>
      <origin rpy="0 0 0" xyz="-0.000200000000003065 0.0199435877845359 0.0292245259211331"/>
      <mass value="0.00853198276973456"/>
      <inertia ixx="2.89328108496468E-06" ixy="-1.57935047237397E-19" ixz="-1.93980378593255E-19" iyy="1.86719750325683E-06" iyz="-1.21858577871576E-06" izz="1.21905238907251E-06"/>
    </inertial>
    <visual>
      <origin rpy="0 0 0" xyz="0 0 0"/>
      <geometry>
        <mesh filename="package://moma_description/grippers/robotiq_2f_85/meshes/visual/robotiq_arg2f_85_outer_knuckle.dae" scale="0.001 0.001 0.001"/>
      </geometry>
      <material name="">
        <color rgba="0.792156862745098 0.819607843137255 0.933333333333333 1"/>
      </material>
    </visual>
    <collision>
      <origin rpy="0 0 0" xyz="0 0 0"/>
      <geometry>
        <mesh filename="package://moma_description/grippers/robotiq_2f_85/meshes/collision/robotiq_arg2f_85_outer_knuckle.dae" scale="0.001 0.001 0.001"/>
      </geometry>
    </collision>
  </link>
  <link name="armleft_outer_finger">
    <inertial>
      <origin rpy="0 0 0" xyz="0.00030115855001899 0.0373907951953854 -0.0208027427000385"/>
      <mass value="0.022614240507152"/>
      <inertia ixx="1.52518312458174E-05" ixy="9.76583423954399E-10" ixz="-5.43838577022588E-10" iyy="6.17694243867776E-06" iyz="6.78636130740228E-06" izz="1.16494917907219E-05"/>
    </inertial>
    <visual>
      <origin rpy="0 0 0" xyz="0 0 0"/>
      <geometry>
        <mesh filename="package://moma_description/grippers/robotiq_2f_85/meshes/visual/robotiq_arg2f_85_outer_finger.dae" scale="0.001 0.001 0.001"/>
      </geometry>
      <material name="">
        <color rgba="0.1 0.1 0.1 1"/>
      </material>
    </visual>
    <collision>
      <origin rpy="0 0 0" xyz="0 0 0"/>
      <geometry>
        <mesh filename="package://moma_description/grippers/robotiq_2f_85/meshes/collision/robotiq_arg2f_85_outer_finger.dae" scale="0.001 0.001 0.001"/>
      </geometry>
    </collision>
  </link>
  <link name="armleft_inner_finger">
    <inertial>
      <origin rpy="0 0 0" xyz="0.000299999999999317 0.0160078233491243 -0.0136945669206257"/>
      <mass value="0.0104003125914103"/>
      <inertia ixx="2.71909453810972E-06" ixy="1.35402465472579E-21" ixz="-7.1817349065269E-22" iyy="7.69100314106116E-07" iyz="6.74715432769696E-07" izz="2.30315190420171E-06"/>
    </inertial>
    <visual>
      <origin rpy="0 0 0" xyz="0 0 0"/>
      <geometry>
        <mesh filename="package://moma_description/grippers/robotiq_2f_85/meshes/visual/robotiq_arg2f_85_inner_finger.dae" scale="0.001 0.001 0.001"/>
      </geometry>
      <material name="">
        <color rgba="0.1 0.1 0.1 1"/>
      </material>
    </visual>
    <collision>
      <origin rpy="0 0 0" xyz="0 0 0"/>
      <geometry>
        <mesh filename="package://moma_description/grippers/robotiq_2f_85/meshes/collision/robotiq_arg2f_85_inner_finger.dae" scale="0.001 0.001 0.001"/>
      </geometry>
    </collision>
  </link>
  <link name="armleft_inner_finger_pad">
    <visual>
      <origin rpy="0 0 0" xyz="0 0 0"/>
      <geometry>
        <box size="0.022 0.00635 0.0375"/>
      </geometry>
      <material name="">
        <color rgba="0.9 0.9 0.9 1"/>
      </material>
    </visual>
    <collision>
      <origin rpy="0 0 0" xyz="0 0 0"/>
      <geometry>
        <box size="0.022 0.00635 0.0375"/>
      </geometry>
      <material name="">
        <color rgba="0.9 0.0 0.0 1"/>
      </material>
    </collision>
  </link>
  <link name="armleft_inner_knuckle">
    <inertial>
      <origin rpy="0 0 0" xyz="0.000123011831763771 0.0507850843201817 0.00103968640075166"/>
      <mass value="0.0271177346495152"/>
      <inertia ixx="2.61910379223783E-05" ixy="-2.43616858946494E-07" ixz="-6.37789906117123E-09" iyy="2.8270243746167E-06" iyz="-5.37200748039765E-07" izz="2.83695868220296E-05"/>
    </inertial>
    <visual>
      <origin rpy="0 0 0" xyz="0 0 0"/>
      <geometry>
        <mesh filename="package://moma_description/grippers/robotiq_2f_85/meshes/visual/robotiq_arg2f_85_inner_knuckle.dae" scale="0.001 0.001 0.001"/>
      </geometry>
      <material name="">
        <color rgba="0.1 0.1 0.1 1"/>
      </material>
    </visual>
    <collision>
      <origin rpy="0 0 0" xyz="0 0 0"/>
      <geometry>
        <mesh filename="package://moma_description/grippers/robotiq_2f_85/meshes/collision/robotiq_arg2f_85_inner_knuckle.dae" scale="0.001 0.001 0.001"/>
      </geometry>
    </collision>
  </link>
  <link name="armright_outer_knuckle">
    <inertial>
      <origin rpy="0 0 0" xyz="-0.000200000000003065 0.0199435877845359 0.0292245259211331"/>
      <mass value="0.00853198276973456"/>
      <inertia ixx="2.89328108496468E-06" ixy="-1.57935047237397E-19" ixz="-1.93980378593255E-19" iyy="1.86719750325683E-06" iyz="-1.21858577871576E-06" izz="1.21905238907251E-06"/>
    </inertial>
    <visual>
      <origin rpy="0 0 0" xyz="0 0 0"/>
      <geometry>
        <mesh filename="package://moma_description/grippers/robotiq_2f_85/meshes/visual/robotiq_arg2f_85_outer_knuckle.dae" scale="0.001 0.001 0.001"/>
      </geometry>
      <material name="">
        <color rgba="0.792156862745098 0.819607843137255 0.933333333333333 1"/>
      </material>
    </visual>
    <collision>
      <origin rpy="0 0 0" xyz="0 0 0"/>
      <geometry>
        <mesh filename="package://moma_description/grippers/robotiq_2f_85/meshes/collision/robotiq_arg2f_85_outer_knuckle.dae" scale="0.001 0.001 0.001"/>
      </geometry>
    </collision>
  </link>
  <link name="armright_outer_finger">
    <inertial>
      <origin rpy="0 0 0" xyz="0.00030115855001899 0.0373907951953854 -0.0208027427000385"/>
      <mass value="0.022614240507152"/>
      <inertia ixx="1.52518312458174E-05" ixy="9.76583423954399E-10" ixz="-5.43838577022588E-10" iyy="6.17694243867776E-06" iyz="6.78636130740228E-06" izz="1.16494917907219E-05"/>
    </inertial>
    <visual>
      <origin rpy="0 0 0" xyz="0 0 0"/>
      <geometry>
        <mesh filename="package://moma_description/grippers/robotiq_2f_85/meshes/visual/robotiq_arg2f_85_outer_finger.dae" scale="0.001 0.001 0.001"/>
      </geometry>
      <material name="">
        <color rgba="0.1 0.1 0.1 1"/>
      </material>
    </visual>
    <collision>
      <origin rpy="0 0 0" xyz="0 0 0"/>
      <geometry>
        <mesh filename="package://moma_description/grippers/robotiq_2f_85/meshes/collision/robotiq_arg2f_85_outer_finger.dae" scale="0.001 0.001 0.001"/>
      </geometry>
    </collision>
  </link>
  <link name="armright_inner_finger">
    <inertial>
      <origin rpy="0 0 0" xyz="0.000299999999999317 0.0160078233491243 -0.0136945669206257"/>
      <mass value="0.0104003125914103"/>
      <inertia ixx="2.71909453810972E-06" ixy="1.35402465472579E-21" ixz="-7.1817349065269E-22" iyy="7.69100314106116E-07" iyz="6.74715432769696E-07" izz="2.30315190420171E-06"/>
    </inertial>
    <visual>
      <origin rpy="0 0 0" xyz="0 0 0"/>
      <geometry>
        <mesh filename="package://moma_description/grippers/robotiq_2f_85/meshes/visual/robotiq_arg2f_85_inner_finger.dae" scale="0.001 0.001 0.001"/>
      </geometry>
      <material name="">
        <color rgba="0.1 0.1 0.1 1"/>
      </material>
    </visual>
    <collision>
      <origin rpy="0 0 0" xyz="0 0 0"/>
      <geometry>
        <mesh filename="package://moma_description/grippers/robotiq_2f_85/meshes/collision/robotiq_arg2f_85_inner_finger.dae" scale="0.001 0.001 0.001"/>
      </geometry>
    </collision>
  </link>
  <link name="armright_inner_finger_pad">
    <visual>
      <origin rpy="0 0 0" xyz="0 0 0"/>
      <geometry>
        <box size="0.022 0.00635 0.0375"/>
      </geometry>
      <material name="">
        <color rgba="0.9 0.9 0.9 1"/>
      </material>
    </visual>
    <collision>
      <origin rpy="0 0 0" xyz="0 0 0"/>
      <geometry>
        <box size="0.022 0.00635 0.0375"/>
      </geometry>
      <material name="">
        <color rgba="0.9 0.0 0.0 1"/>
      </material>
    </collision>
  </link>
  <link name="armright_inner_knuckle">
    <inertial>
      <origin rpy="0 0 0" xyz="0.000123011831763771 0.0507850843201817 0.00103968640075166"/>
      <mass value="0.0271177346495152"/>
      <inertia ixx="2.61910379223783E-05" ixy="-2.43616858946494E-07" ixz="-6.37789906117123E-09" iyy="2.8270243746167E-06" iyz="-5.37200748039765E-07" izz="2.83695868220296E-05"/>
    </inertial>
    <visual>
      <origin rpy="0 0 0" xyz="0 0 0"/>
      <geometry>
        <mesh filename="package://moma_description/grippers/robotiq_2f_85/meshes/visual/robotiq_arg2f_85_inner_knuckle.dae" scale="0.001 0.001 0.001"/>
      </geometry>
      <material name="">
        <color rgba="0.1 0.1 0.1 1"/>
      </material>
    </visual>
    <collision>
      <origin rpy="0 0 0" xyz="0 0 0"/>
      <geometry>
        <mesh filename="package://moma_description/grippers/robotiq_2f_85/meshes/collision/robotiq_arg2f_85_inner_knuckle.dae" scale="0.001 0.001 0.001"/>
      </geometry>
    </collision>
  </link>
  <joint name="armfinger_joint" type="fixed">
    <origin rpy="0 0 3.141592653589793" xyz="0 -0.0306011 0.054904"/>
    <parent link="armrobotiq_arg2f_base_link"/>
    <child link="armleft_outer_knuckle"/>
    <axis xyz="1 0 0"/>
    <limit effort="1000" lower="0" upper="0.8" velocity="2.0"/>
  </joint>
  <joint name="armleft_outer_finger_joint" type="fixed">
    <origin rpy="0 0 0" xyz="0 0.0315 -0.0041"/>
    <parent link="armleft_outer_knuckle"/>
    <child link="armleft_outer_finger"/>
    <axis xyz="1 0 0"/>
  </joint>
  <joint name="armleft_inner_knuckle_joint" type="fixed">
    <!-- <origin xyz="0 ${reflect * -0.0127} 0.06142" rpy="${pi / 2 + .725} 0 ${(reflect - 1) * pi / 2}" /> -->
    <origin rpy="0 0 3.141592653589793" xyz="0 -0.0127 0.06142"/>
    <parent link="armrobotiq_arg2f_base_link"/>
    <child link="armleft_inner_knuckle"/>
    <axis xyz="1 0 0"/>
    <limit effort="1000" lower="0" upper="0.8757" velocity="2.0"/>
    <mimic joint="armfinger_joint" multiplier="1" offset="0"/>
  </joint>
  <joint name="armleft_inner_finger_joint" type="fixed">
    <origin rpy="0 0 0" xyz="0 0.0061 0.0471"/>
    <parent link="armleft_outer_finger"/>
    <child link="armleft_inner_finger"/>
    <axis xyz="1 0 0"/>
    <limit effort="1000" lower="-0.8757" upper="0.8757" velocity="2.0"/>
    <mimic joint="armfinger_joint" multiplier="-1" offset="0"/>
  </joint>
  <joint name="armleft_inner_finger_pad_joint" type="fixed">
    <origin rpy="0 0 0" xyz="0 -0.0220203446692936 0.03242"/>
    <parent link="armleft_inner_finger"/>
    <child link="armleft_inner_finger_pad"/>
    <axis xyz="0 0 1"/>
  </joint>
  <joint name="armright_outer_knuckle_joint" type="fixed">
    <origin rpy="0 0 0" xyz="0 0.0306011 0.054904"/>
    <parent link="armrobotiq_arg2f_base_link"/>
    <child link="armright_outer_knuckle"/>
    <axis xyz="1 0 0"/>
    <limit effort="1000" lower="0" upper="0.81" velocity="2.0"/>
    <mimic joint="armfinger_joint" multiplier="1" offset="0"/>
  </joint>
  <joint name="armright_outer_finger_joint" type="fixed">
    <origin rpy="0 0 0" xyz="0 0.0315 -0.0041"/>
    <parent link="armright_outer_knuckle"/>
    <child link="armright_outer_finger"/>
    <axis xyz="1 0 0"/>
  </joint>
  <joint name="armright_inner_knuckle_joint" type="fixed">
    <!-- <origin xyz="0 ${reflect * -0.0127} 0.06142" rpy="${pi / 2 + .725} 0 ${(reflect - 1) * pi / 2}" /> -->
    <origin rpy="0 0 0.0" xyz="0 0.0127 0.06142"/>
    <parent link="armrobotiq_arg2f_base_link"/>
    <child link="armright_inner_knuckle"/>
    <axis xyz="1 0 0"/>
    <limit effort="1000" lower="0" upper="0.8757" velocity="2.0"/>
    <mimic joint="armfinger_joint" multiplier="1" offset="0"/>
  </joint>
  <joint name="armright_inner_finger_joint" type="fixed">
    <origin rpy="0 0 0" xyz="0 0.0061 0.0471"/>
    <parent link="armright_outer_finger"/>
    <child link="armright_inner_finger"/>
    <axis xyz="1 0 0"/>
    <limit effort="1000" lower="-0.8757" upper="0.8757" velocity="2.0"/>
    <mimic joint="armfinger_joint" multiplier="-1" offset="0"/>
  </joint>
  <joint name="armright_inner_finger_pad_joint" type="fixed">
    <origin rpy="0 0 0" xyz="0 -0.0220203446692936 0.03242"/>
    <parent link="armright_inner_finger"/>
    <child link="armright_inner_finger_pad"/>
    <axis xyz="0 0 1"/>
  </joint>
  <!-- Transmissions are loaded in the generic kortex xacro when simulation is enabled -->
  <!-- <xacro:robotiq_arg2f_transmission prefix="${prefix}"/> -->
  <link name="base_link">
    <inertial>
      <origin rpy="0 0 0" xyz="-0.23919 -0.0076434 0.16725"/>
      <mass value="0.13901"/>
      <inertia ixx="3.9034E-05" ixy="-3.8116E-21" ixz="-6.9162E-21" iyy="2.9524E-05" iyz="1.1415E-08" izz="2.3359E-05"/>
    </inertial>
    <visual>
      <origin rpy="0 0 0" xyz="0 0 0"/>
      <geometry>
        <mesh filename="package://moma_description/meshes/base_link.STL"/>
      </geometry>
      <material name="">
        <color rgba="0 0 0 1"/>
      </material>
    </visual>
    <collision>
      <geometry>
        <box size="0.6 0.4 0.16"/>
      </geometry>
      <origin rpy="0 0 0" xyz="0 -0.008 0.154"/>
    </collision>
  </link>
  <link name="lf_Link">
    <inertial>
      <origin rpy="0 0 0" xyz="-1.4413E-06 -0.044165 1.4709E-06"/>
      <mass value="2.716"/>
      <inertia ixx="0.006971" ixy="-8.4556E-08" ixz="3.237E-08" iyy="0.010586" iyz="2.5235E-07" izz="0.0069709"/>
    </inertial>
    <visual>
      <origin rpy="0 0 0" xyz="0 0 0"/>
      <geometry>
        <mesh filename="package://moma_description/meshes/lf_Link.STL"/>
      </geometry>
      <material name="">
        <color rgba="0.37 0.37 0.37 1"/>
      </material>
    </visual>
    <collision>
      <geometry>
        <cylinder length="0.1" radius="0.083"/>
      </geometry>
      <origin rpy="1.5708 0 0" xyz="0 -0.05 0"/>
    </collision>
  </link>
  <joint name="lf_Joint" type="fixed">
    <origin rpy="0 0 0" xyz="0.20606 0.302 0.082983"/>
    <parent link="base_link"/>
    <child link="lf_Link"/>
    <axis xyz="0 -1 0"/>
  </joint>
  <link name="lb_Link">
    <inertial>
      <origin rpy="0 0 0" xyz="1.6945E-06 -0.044165 -1.1688E-06"/>
      <mass value="2.716"/>
      <inertia ixx="0.0069709" ixy="2.6308E-07" ixz="1.4965E-08" iyy="0.010586" iyz="-4.0208E-08" izz="0.006971"/>
    </inertial>
    <visual>
      <origin rpy="0 0 0" xyz="0 0 0"/>
      <geometry>
        <mesh filename="package://moma_description/meshes/lb_Link.STL"/>
      </geometry>
      <material name="">
        <color rgba="0.37 0.37 0.37 1"/>
      </material>
    </visual>
    <collision>
      <geometry>
        <cylinder length="0.1" radius="0.083"/>
      </geometry>
      <origin rpy="1.5708 0 0" xyz="0 -0.05 0"/>
    </collision>
  </link>
  <joint name="lb_Joint" type="fixed">
    <origin rpy="0 0 0" xyz="-0.20666 0.302 0.082983"/>
    <parent link="base_link"/>
    <child link="lb_Link"/>
    <axis xyz="0 -1 0"/>
  </joint>
  <link name="rf_Link">
    <inertial>
      <origin rpy="0 0 0" xyz="8.5684E-07 0.044165 -1.8717E-06"/>
      <mass value="2.716"/>
      <inertia ixx="0.006971" ixy="6.0861E-09" ixz="-4.4919E-09" iyy="0.010586" iyz="2.6607E-07" izz="0.0069709"/>
    </inertial>
    <visual>
      <origin rpy="0 0 0" xyz="0 0 0"/>
      <geometry>
        <mesh filename="package://moma_description/meshes/rf_Link.STL"/>
      </geometry>
      <material name="">
        <color rgba="0.37 0.37 0.37 1"/>
      </material>
    </visual>
    <collision>
      <geometry>
        <cylinder length="0.1" radius="0.083"/>
      </geometry>
      <origin rpy="1.5708 0 0" xyz="0 0.05 0"/>
    </collision>
  </link>
  <joint name="rf_Joint" type="fixed">
    <origin rpy="0 0 0" xyz="0.20606 -0.3173 0.082983"/>
    <parent link="base_link"/>
    <child link="rf_Link"/>
    <axis xyz="0 1 0"/>
  </joint>
  <link name="rb_Link">
    <inertial>
      <origin rpy="0 0 0" xyz="-1.1983E-06 0.044165 1.6748E-06"/>
      <mass value="2.716"/>
      <inertia ixx="0.006971" ixy="2.3383E-07" ixz="4.6185E-08" iyy="0.010586" iyz="-1.2709E-07" izz="0.006971"/>
    </inertial>
    <visual>
      <origin rpy="0 0 0" xyz="0 0 0"/>
      <geometry>
        <mesh filename="package://moma_description/meshes/rb_Link.STL"/>
      </geometry>
      <material name="">
        <color rgba="0.37 0.37 0.37 1"/>
      </material>
    </visual>
    <collision>
      <geometry>
        <cylinder length="0.1" radius="0.083"/>
      </geometry>
      <origin rpy="1.5708 0 0" xyz="0 0.05 0"/>
    </collision>
  </link>
  <joint name="rb_Joint" type="fixed">
    <origin rpy="0 0 0" xyz="-0.20666 -0.3173 0.082983"/>
    <parent link="base_link"/>
    <child link="rb_Link"/>
    <axis xyz="0 1 0"/>
  </joint>
  <link name="radar_Link">
    <inertial>
      <origin rpy="0 0 0" xyz="-0.00023725 4.4243E-08 -0.035474"/>
      <mass value="0.12465"/>
      <inertia ixx="3.641E-05" ixy="-2.9136E-11" ixz="-3.049E-07" iyy="3.9658E-05" iyz="-1.358E-10" izz="5.8108E-05"/>
    </inertial>
    <visual>
      <origin rpy="0 0 0" xyz="0 0 0"/>
      <geometry>
        <mesh filename="package://moma_description/meshes/radar_Link.STL"/>
      </geometry>
      <material name="">
        <color rgba="0.75 0.75 0.75 1"/>
      </material>
    </visual>
    <collision>
      <geometry>
        <box size="0.06 0.06 0.05"/>
      </geometry>
      <origin rpy="0 0 0" xyz="0 0 -0.023"/>
    </collision>
  </link>
  <joint name="radar_Joint" type="fixed">
    <origin rpy="0 0 0" xyz="-0.17765 -0.0076466 0.36849"/>
    <parent link="base_link"/>
    <child link="radar_Link"/>
    <axis xyz="0 0 1"/>
  </joint>
  <link name="print_Link">
    <inertial>
      <origin rpy="0 0 0" xyz="-0.13941 -0.0076465 0.15857"/>
      <mass value="0.048817"/>
      <inertia ixx="6.8735E-05" ixy="1.1947E-12" ixz="2.6312E-07" iyy="2.366E-05" iyz="2.8424E-13" izz="8.7334E-05"/>
    </inertial>
    <visual>
      <origin rpy="0 0 0" xyz="0 0 0"/>
      <geometry>
        <mesh filename="package://moma_description/meshes/print_Link.STL"/>
      </geometry>
      <material name="">
        <color rgba="0 0.5 1 1"/>
      </material>
    </visual>
  </link>
  <joint name="print_Joint" type="fixed">
    <origin rpy="0 0 0" xyz="0 0 0"/>
    <parent link="base_link"/>
    <child link="print_Link"/>
    <axis xyz="0 0 1"/>
  </joint>
  <link name="other_Link">
    <inertial>
      <origin rpy="0 0 0" xyz="-0.0066087 -0.0071056 0.17596"/>
      <mass value="7.6241"/>
      <inertia ixx="0.069495" ixy="-0.00011835" ixz="0.00051871" iyy="0.12492" iyz="8.9487E-06" izz="0.18996"/>
    </inertial>
    <visual>
      <origin rpy="0 0 0" xyz="0 0 0"/>
      <geometry>
        <mesh filename="package://moma_description/meshes/other_Link.STL"/>
      </geometry>
      <material name="">
        <color rgba="0.5 0.5 0.5 1"/>
      </material>
    </visual>
    <collision>
      <geometry>
        <box size="0.4 0.3 0.06"/>
      </geometry>
      <origin rpy="0 0 0" xyz="0 0 0.274"/>
    </collision>
  </link>
  <joint name="other_Joint" type="fixed">
    <origin rpy="0 0 0" xyz="0 0 0"/>
    <parent link="base_link"/>
    <child link="other_Link"/>
    <axis xyz="0 0 1"/>
  </joint>
  <link name="root"/>
  <joint name="planar_move" type="fixed">
    <parent link="root"/>
    <child link="base_link"/>
    <origin rpy="0 0 0" xyz="0 0 0"/>
  </joint>
  <joint name="arm_to_chassis" type="fixed">
    <parent link="base_link"/>
    <child link="armbase_link"/>
    <origin rpy="0 0 0" xyz="0.03385 -0.00764 0.306"/>
  </joint>
  <!-- <link name="end_effector_link"/>
  <joint name="end_effector_joint" type="fixed">
    <parent link="armend_effector_link"/>
    <child link="end_effector_link"/>
    <origin rpy="0 0 0" xyz="0 0 0.11"/>
  </joint> -->
  <gazebo reference="base_link">
    <self_collide>true</self_collide>
  </gazebo>
  <gazebo reference="lf_Link">
    <self_collide>true</self_collide>
  </gazebo>
  <gazebo reference="lb_Link">
    <self_collide>true</self_collide>
  </gazebo>
  <gazebo reference="rf_Link">
    <self_collide>true</self_collide>
  </gazebo>
  <gazebo reference="rb_Link">
    <self_collide>true</self_collide>
  </gazebo>
  <gazebo reference="radar_Link">
    <self_collide>true</self_collide>
  </gazebo>
  <gazebo reference="print_Link">
    <self_collide>true</self_collide>
  </gazebo>
  <gazebo reference="other_Link">
    <self_collide>true</self_collide>
  </gazebo>

  
    <transmission name="trans_joint_X">
        <type>transmission_interface/SimpleTransmission</type>
        <joint name="joint_X">
            <hardwareInterface>hardware_interface/EffortJointInterface</hardwareInterface>
        </joint>
        <actuator name="joint_X_motor">
            <hardwareInterface>hardware_interface/EffortJointInterface</hardwareInterface>
            <mechanicalReduction>1</mechanicalReduction>
        </actuator>
    </transmission>
    <transmission name="trans_joint_Y">
        <type>transmission_interface/SimpleTransmission</type>
        <joint name="joint_Y">
            <hardwareInterface>hardware_interface/EffortJointInterface</hardwareInterface>
        </joint>
        <actuator name="joint_Y_motor">
            <hardwareInterface>hardware_interface/EffortJointInterface</hardwareInterface>
            <mechanicalReduction>1</mechanicalReduction>
        </actuator>
    </transmission>
    <transmission name="trans_joint_yaw">
        <type>transmission_interface/SimpleTransmission</type>
        <joint name="joint_yaw">
            <hardwareInterface>hardware_interface/EffortJointInterface</hardwareInterface>
        </joint>
        <actuator name="joint_yaw_motor">
            <hardwareInterface>hardware_interface/EffortJointInterface</hardwareInterface>
            <mechanicalReduction>1</mechanicalReduction>
        </actuator>
    </transmission>

</robot>
